<?xml version="1.0" encoding="utf-8"?>
<sdf version="1,5">
  <model name="Demo Robot">
    <pose>0 0 0,1965 0 0 0</pose>
    <plugin name="clock" filename="libgz_clock.so">
      <topic>/gazebo/frc/time</topic>
    </plugin>
    <link name="L_Base">
      <gravity>1</gravity>
      <self_collide>0</self_collide>
      <pose>0,0324999877251371 -0,0275438384153894 -0,0118671448576802 6,43014044029318E-32 -5,85057606841884E-16 3,14159265358979</pose>
      <must_be_base_link>1</must_be_base_link>
      <velocity_decay>
        <linear>0</linear>
        <angular>0</angular>
      </velocity_decay>
      <inertial>
        <mass>0,96917176777913</mass>
        <pose>0 0 0 0 0 0</pose>
        <inertia>
          <ixx>0,0102912929571195</ixx>
          <ixy>1,45167155006996E-10</ixy>
          <ixz>8,9502460444829E-09</ixz>
          <iyy>0,00939746936704704</iyy>
          <iyz>0,000320156195003978</iyz>
          <izz>0,00149595620877271</izz>
        </inertia>
      </inertial>
      <visual name="L_Base_visual">
        <pose>0,0236422196773824 0,0133066043650966 -0,12605845273747 0 0 0</pose>
        <material>
          <ambient>0,501960784313725 0,501960784313725 0,501960784313725 1</ambient>
          <diffuse>0,501960784313725 0,501960784313725 0,501960784313725 1</diffuse>
        </material>
        <geometry>
          <mesh>
            <scale>1 1 1</scale>
            <uri>model://Demo_Robot/meshes/L_Base.STL</uri>
          </mesh>
        </geometry>
      </visual>
    </link>
    <link name="L_Link1">
      <gravity>1</gravity>
      <self_collide>0</self_collide>
      <pose>0,0325949669028882 -0,0968741334586197 0,0229914721937373 6,43014044029318E-32 -5,85057606841884E-16 3,14159265358979</pose>
      <must_be_base_link>0</must_be_base_link>
      <velocity_decay>
        <linear>0</linear>
        <angular>0</angular>
      </velocity_decay>
      <inertial>
        <mass>0,164736245101744</mass>
        <pose>0 0 0 0 0 0</pose>
        <inertia>
          <ixx>0,000354922017417902</ixx>
          <ixy>5,35269096625066E-07</ixy>
          <ixz>8,92716845258185E-09</ixz>
          <iyy>3,40410404957E-05</iyy>
          <iyz>5,42420313631755E-06</iyz>
          <izz>0,000380337203412796</izz>
        </inertia>
      </inertial>
      <visual name="L_Link1_visual">
        <pose>0,0237371988551334 -0,0560236906781337 -0,160917069788888 0 0 0</pose>
        <material>
          <ambient>1 0 0 1</ambient>
          <diffuse>1 0 0 1</diffuse>
        </material>
        <geometry>
          <mesh>
            <scale>1 1 1</scale>
            <uri>model://Demo_Robot/meshes/L_Link1.STL</uri>
          </mesh>
        </geometry>
      </visual>
    </link>
    <joint name="L_Base-L_Link1" type="revolute">
      <parent>L_Base</parent>
      <child>L_Link1</child>
      <pose>9,49669028882869E-05 -0,0568741334586197 -4,9960036108132E-16 0 1,5707963267949 0</pose>
      <axis>
        <xyz>-1 0 2,22044604925031E-16</xyz>
        <dynamics>
          <damping>0</damping>
          <friction>0</friction>
        </dynamics>
        <limit>
          <upper>2,4576058777699</upper>
          <lower>-2,4609463196602</lower>
          <effort>1</effort>
        </limit>
      </axis>
    </joint>
    <link name="L_Link2">
      <gravity>1</gravity>
      <self_collide>0</self_collide>
      <pose>0,0792709497586049 -0,0398095604242945 -0,0375411962661503 6,43014044029318E-32 -5,85057606841884E-16 3,14159265358979</pose>
      <must_be_base_link>0</must_be_base_link>
      <velocity_decay>
        <linear>0</linear>
        <angular>0</angular>
      </velocity_decay>
      <inertial>
        <mass>0,0748820783167836</mass>
        <pose>0 0 0 0 0 0</pose>
        <inertia>
          <ixx>1,61305607068798E-05</ixx>
          <ixy>2,13810480132766E-06</ixy>
          <ixz>1,55858814971233E-06</ixz>
          <iyy>0,000168484871506324</iyy>
          <iyz>4,27150639932209E-07</iyz>
          <izz>0,000177796289725799</izz>
        </inertia>
      </inertial>
      <visual name="L_Link2_visual">
        <pose>0,0704131817108502 0,00104088235619147 -0,100384401329 0 0 0</pose>
        <material>
          <ambient>0 1 0 1</ambient>
          <diffuse>0 1 0 1</diffuse>
        </material>
        <geometry>
          <mesh>
            <scale>1 1 1</scale>
            <uri>model://Demo_Robot/meshes/L_Link2.STL</uri>
          </mesh>
        </geometry>
      </visual>
    </link>
    <joint name="L_Base-L_Link2" type="revolute">
      <parent>L_Base</parent>
      <child>L_Link2</child>
      <pose>0,0467710514764034 0,000190541293504092 6,93889390390723E-17 0 1,5707963267949 0</pose>
      <axis>
        <xyz>1 0 -2,22044604925031E-16</xyz>
        <dynamics>
          <damping>0</damping>
          <friction>0</friction>
        </dynamics>
        <limit>
          <upper>0</upper>
          <lower>-4,03564696737972</lower>
          <effort>1</effort>
        </limit>
      </axis>
    </joint>
    <link name="L_Link3">
      <gravity>1</gravity>
      <self_collide>0</self_collide>
      <pose>0,152598983247323 -0,100668992817579 -0,0173375 6,43014044029318E-32 -5,85057606841884E-16 3,14159265358979</pose>
      <must_be_base_link>0</must_be_base_link>
      <velocity_decay>
        <linear>0</linear>
        <angular>0</angular>
      </velocity_decay>
      <inertial>
        <mass>0,156153324497507</mass>
        <pose>0 0 0 0 0 0</pose>
        <inertia>
          <ixx>0,000323546877105248</ixx>
          <ixy>4,90610074391702E-07</ixy>
          <ixz>3,79832936949938E-20</ixz>
          <iyy>3,19513171546439E-05</iyy>
          <iyz>1,33949130094875E-19</iyz>
          <izz>0,000348939347981714</izz>
        </inertia>
      </inertial>
      <visual name="L_Link3_visual">
        <pose>0,143741215199568 -0,0598185500370931 -0,12058809759515 0 0 0</pose>
        <material>
          <ambient>0,752941176470588 0,752941176470588 0,752941176470588 1</ambient>
          <diffuse>0,752941176470588 0,752941176470588 0,752941176470588 1</diffuse>
        </material>
        <geometry>
          <mesh>
            <scale>1 1 1</scale>
            <uri>model://Demo_Robot/meshes/L_Link3.STL</uri>
          </mesh>
        </geometry>
      </visual>
    </link>
    <joint name="L_Link2-L_Link3" type="revolute">
      <parent>L_Link2</parent>
      <child>L_Link3</child>
      <pose>0,000100949683442098 -0,059999915076285 2,77555756156289E-17 0 4,71238898038469 0</pose>
      <axis>
        <xyz>-1 -3,58699641135531E-16 1,68478624100026E-15</xyz>
        <dynamics>
          <damping>0</damping>
          <friction>0</friction>
        </dynamics>
        <limit>
          <effort>1</effort>
        </limit>
      </axis>
    </joint>
    <link name="L_Link4">
      <gravity>1</gravity>
      <self_collide>0</self_collide>
      <pose>0,0327010949057605 -0,16000082060123 0,00253750000000005 6,43014044029318E-32 -5,85057606841884E-16 3,14159265358979</pose>
      <must_be_base_link>0</must_be_base_link>
      <velocity_decay>
        <linear>0</linear>
        <angular>0</angular>
      </velocity_decay>
      <inertial>
        <mass>0,269221640157259</mass>
        <pose>0 0 0 0 0 0</pose>
        <inertia>
          <ixx>5,72191233182153E-05</ixx>
          <ixy>9,42271216414319E-06</ixy>
          <ixz>1,00492643515816E-18</ixz>
          <iyy>0,0017474004782036</iyy>
          <iyz>1,39139193131457E-20</iyz>
          <izz>0,00179331159153719</izz>
        </inertia>
      </inertial>
      <visual name="L_Link4_visual">
        <pose>0,0238433268580058 -0,119150377820744 -0,14046309759515 0 0 0</pose>
        <material>
          <ambient>0,752941176470588 0,752941176470588 0,752941176470588 1</ambient>
          <diffuse>0,752941176470588 0,752941176470588 0,752941176470588 1</diffuse>
        </material>
        <geometry>
          <mesh>
            <scale>1 1 1</scale>
            <uri>model://Demo_Robot/meshes/L_Link4.STL</uri>
          </mesh>
        </geometry>
      </visual>
    </link>
    <joint name="L_Link3-L_Link4" type="revolute">
      <parent>L_Link3</parent>
      <child>L_Link4</child>
      <pose>-0,119998838025005 0,000668087292634248 1,66533453693773E-16 0 4,71238898038469 0</pose>
      <axis>
        <xyz>-1 -3,58699641135531E-16 1,68478624100026E-15</xyz>
        <dynamics>
          <damping>0</damping>
          <friction>0</friction>
        </dynamics>
        <limit>
          <effort>1</effort>
        </limit>
      </axis>
    </joint>
    <joint name="L_Link1-L_Link4" type="revolute">
      <parent>L_Link1</parent>
      <child>L_Link4</child>
      <pose>7,70203326741492E-07 -8,8626167209227E-07 0 0 4,71238898038469 0</pose>
      <axis>
        <xyz>-1 0 2,22044604925031E-16</xyz>
        <dynamics>
          <damping>0</damping>
          <friction>0</friction>
        </dynamics>
        <limit>
          <effort>1</effort>
        </limit>
      </axis>
    </joint>
    <plugin name="L_Base-L_Link1_motor" filename="libgz_dc_motor.so">
      <joint>L_Base-L_Link1</joint>
      <topic>/gazebo/frc/simulator/pwm/3</topic>
      <multiplier>0</multiplier>
    </plugin>
    <plugin name="L_Base-L_Link1_encoder" filename="libgz_encoder.so">
      <joint>L_Base-L_Link1</joint>
      <topic>/gazebo/frc/simulator/dio/0/0</topic>
      <units>degrees</units>
    </plugin>
    <plugin name="L_Base-L_Link2_motor" filename="libgz_dc_motor.so">
      <joint>L_Base-L_Link2</joint>
      <topic>/gazebo/frc/simulator/pwm/0</topic>
      <multiplier>0</multiplier>
    </plugin>
    <plugin name="L_Base-L_Link2_encoder" filename="libgz_encoder.so">
      <joint>L_Base-L_Link2</joint>
      <topic>/gazebo/frc/simulator/dio/0/0</topic>
      <units>degrees</units>
    </plugin>
  </model>
</sdf>